<?xml version="1.0" ?>
<robot name="hexapod" xmlns:xacro="http://www.ros.org/wiki/xacro">

<xacro:include filename="$(find hexapod_description)/urdf/materials.xacro" />
<xacro:include filename="$(find hexapod_description)/urdf/hexapod.trans" />
<xacro:include filename="$(find hexapod_description)/urdf/hexapod.gazebo" />
<xacro:include filename="$(find hexapod_control)/ros2_control/ros2_control.xacro" />

<link name="base_link">
  <inertial>
    <origin xyz="0.10909777793044037 0.06468612005136756 0.006889314215312581" rpy="0 0 0"/>
    <mass value="14.09466584247892"/>
    <inertia ixx="0.168182" iyy="0.074083" izz="0.200235" ixy="0.006215" iyz="0.001309" ixz="-0.000356"/>
  </inertial>
  <visual>
    <origin xyz="0 0 0" rpy="0 0 0"/>
    <geometry>
      <mesh filename="file://$(find hexapod_description)/meshes/base_link.stl" scale="0.001 0.001 0.001"/>
    </geometry>
    <material name="silver"/>
  </visual>
  <collision>
    <origin xyz="0 0 0" rpy="0 0 0"/>
    <geometry>
      <mesh filename="file://$(find hexapod_description)/meshes/base_link.stl" scale="0.001 0.001 0.001"/>
    </geometry>
  </collision>
</link>

<link name="leg_1_coxa_1">
  <inertial>
    <origin xyz="-0.02800590467788834 0.004191461427254562 -0.05523214859518318" rpy="0 0 0"/>
    <mass value="1.012661950148346"/>
    <inertia ixx="0.000816" iyy="0.001315" izz="0.00101" ixy="-0.000122" iyz="-8.3e-05" ixz="-0.000522"/>
  </inertial>
  <visual>
    <origin xyz="0.003565 0.030766 -0.036053" rpy="0 0 0"/>
    <geometry>
      <mesh filename="file://$(find hexapod_description)/meshes/leg_1_coxa_1.stl" scale="0.001 0.001 0.001"/>
    </geometry>
    <material name="gold"/>
  </visual>
  <collision>
    <origin xyz="0.003565 0.030766 -0.036053" rpy="0 0 0"/>
    <geometry>
      <mesh filename="file://$(find hexapod_description)/meshes/leg_1_coxa_1.stl" scale="0.001 0.001 0.001"/>
    </geometry>
  </collision>
</link>

<link name="leg_1_femur_1">
  <inertial>
    <origin xyz="-0.03522346741409946 0.024775287767070026 0.03589434090766965" rpy="0 0 0"/>
    <mass value="0.22871600239093776"/>
    <inertia ixx="0.000319" iyy="0.000276" izz="0.00031" ixy="-2e-06" iyz="-2e-06" ixz="0.000128"/>
  </inertial>
  <visual>
    <origin xyz="0.071402 0.062467 0.04316" rpy="0 0 0"/>
    <geometry>
      <mesh filename="file://$(find hexapod_description)/meshes/leg_1_femur_1.stl" scale="0.001 0.001 0.001"/>
    </geometry>
    <material name="silver"/>
  </visual>
  <collision>
    <origin xyz="0.071402 0.062467 0.04316" rpy="0 0 0"/>
    <geometry>
      <mesh filename="file://$(find hexapod_description)/meshes/leg_1_femur_1.stl" scale="0.001 0.001 0.001"/>
    </geometry>
  </collision>
</link>

<link name="leg_1_tibia_1">
  <inertial>
    <origin xyz="-0.016678656476565135 0.028724980437268344 -0.024504789085526477" rpy="0 0 0"/>
    <mass value="0.907399585528797"/>
    <inertia ixx="0.002924" iyy="0.003176" izz="0.000422" ixy="-2.3e-05" iyz="-2e-05" ixz="-0.000767"/>
  </inertial>
  <visual>
    <origin xyz="0.140961 0.062723 -0.028684" rpy="0 0 0"/>
    <geometry>
      <mesh filename="file://$(find hexapod_description)/meshes/leg_1_tibia_1.stl" scale="0.001 0.001 0.001"/>
    </geometry>
    <material name="silver"/>
  </visual>
  <collision>
    <origin xyz="0.140961 0.062723 -0.028684" rpy="0 0 0"/>
    <geometry>
      <mesh filename="file://$(find hexapod_description)/meshes/leg_1_tibia_1.stl" scale="0.001 0.001 0.001"/>
    </geometry>
  </collision>
</link>

<link name="leg_3_coxa_1">
  <inertial>
    <origin xyz="-0.02800203130695705 0.004225621248029748 -0.05523202595087612" rpy="0 0 0"/>
    <mass value="1.0126620006859057"/>
    <inertia ixx="0.000815" iyy="0.001315" izz="0.001011" ixy="-0.000122" iyz="-8.2e-05" ixz="-0.000522"/>
  </inertial>
  <visual>
    <origin xyz="-0.00013 -0.229172 -0.040385" rpy="0 0 0"/>
    <geometry>
      <mesh filename="file://$(find hexapod_description)/meshes/leg_3_coxa_1.stl" scale="0.001 0.001 0.001"/>
    </geometry>
    <material name="gold"/>
  </visual>
  <collision>
    <origin xyz="-0.00013 -0.229172 -0.040385" rpy="0 0 0"/>
    <geometry>
      <mesh filename="file://$(find hexapod_description)/meshes/leg_3_coxa_1.stl" scale="0.001 0.001 0.001"/>
    </geometry>
  </collision>
</link>

<link name="leg_3_femur_1">
  <inertial>
    <origin xyz="-0.03518763654515632 0.024818021713592847 0.035899561715590445" rpy="0 0 0"/>
    <mass value="0.2287158182027981"/>
    <inertia ixx="0.000319" iyy="0.000276" izz="0.00031" ixy="-2e-06" iyz="-2e-06" ixz="0.000128"/>
  </inertial>
  <visual>
    <origin xyz="0.067748 -0.197555 0.038827" rpy="0 0 0"/>
    <geometry>
      <mesh filename="file://$(find hexapod_description)/meshes/leg_3_femur_1.stl" scale="0.001 0.001 0.001"/>
    </geometry>
    <material name="silver"/>
  </visual>
  <collision>
    <origin xyz="0.067748 -0.197555 0.038827" rpy="0 0 0"/>
    <geometry>
      <mesh filename="file://$(find hexapod_description)/meshes/leg_3_femur_1.stl" scale="0.001 0.001 0.001"/>
    </geometry>
  </collision>
</link>

<link name="leg_3_tibia_1">
  <inertial>
    <origin xyz="-0.016646092528238454 0.028744708254966528 -0.02450268109763687" rpy="0 0 0"/>
    <mass value="0.9073986789846695"/>
    <inertia ixx="0.002924" iyy="0.003177" izz="0.000422" ixy="-2.3e-05" iyz="-1.9e-05" ixz="-0.000768"/>
  </inertial>
  <visual>
    <origin xyz="0.137297 -0.197385 -0.033027" rpy="0 0 0"/>
    <geometry>
      <mesh filename="file://$(find hexapod_description)/meshes/leg_3_tibia_1.stl" scale="0.001 0.001 0.001"/>
    </geometry>
    <material name="silver"/>
  </visual>
  <collision>
    <origin xyz="0.137297 -0.197385 -0.033027" rpy="0 0 0"/>
    <geometry>
      <mesh filename="file://$(find hexapod_description)/meshes/leg_3_tibia_1.stl" scale="0.001 0.001 0.001"/>
    </geometry>
  </collision>
</link>

<link name="leg_4_coxa_1">
  <inertial>
    <origin xyz="0.027993744733458475 0.0032113221383066846 -0.055366199346642296" rpy="0 0 0"/>
    <mass value="1.0132520108724496"/>
    <inertia ixx="0.000828" iyy="0.001314" izz="0.001012" ixy="0.000137" iyz="-9.9e-05" ixz="0.000522"/>
  </inertial>
  <visual>
    <origin xyz="-0.212413 0.03383 -0.035672" rpy="0 0 0"/>
    <geometry>
      <mesh filename="file://$(find hexapod_description)/meshes/leg_4_coxa_1.stl" scale="0.001 0.001 0.001"/>
    </geometry>
    <material name="gold"/>
  </visual>
  <collision>
    <origin xyz="-0.212413 0.03383 -0.035672" rpy="0 0 0"/>
    <geometry>
      <mesh filename="file://$(find hexapod_description)/meshes/leg_4_coxa_1.stl" scale="0.001 0.001 0.001"/>
    </geometry>
  </collision>
</link>

<link name="leg_5_coxa_1">
  <inertial>
    <origin xyz="0.027997279263115404 0.00316168260604871 -0.05536637501356985" rpy="0 0 0"/>
    <mass value="1.0132520108724496"/>
    <inertia ixx="0.000828" iyy="0.001313" izz="0.001012" ixy="0.000138" iyz="-9.9e-05" ixz="0.000522"/>
  </inertial>
  <visual>
    <origin xyz="-0.22226 -0.096026 -0.037823" rpy="0 0 0"/>
    <geometry>
      <mesh filename="file://$(find hexapod_description)/meshes/leg_5_coxa_1.stl" scale="0.001 0.001 0.001"/>
    </geometry>
    <material name="gold"/>
  </visual>
  <collision>
    <origin xyz="-0.22226 -0.096026 -0.037823" rpy="0 0 0"/>
    <geometry>
      <mesh filename="file://$(find hexapod_description)/meshes/leg_5_coxa_1.stl" scale="0.001 0.001 0.001"/>
    </geometry>
  </collision>
</link>

<link name="leg_5_femur_1">
  <inertial>
    <origin xyz="0.03603602445571802 0.02375358680070326 0.035773642331451645" rpy="0 0 0"/>
    <mass value="0.22866968962750417"/>
    <inertia ixx="0.000318" iyy="0.000276" izz="0.00031" ixy="1e-06" iyz="1e-06" ixz="-0.000128"/>
  </inertial>
  <visual>
    <origin xyz="-0.289378 -0.06214 0.041845" rpy="0 0 0"/>
    <geometry>
      <mesh filename="file://$(find hexapod_description)/meshes/leg_5_femur_1.stl" scale="0.001 0.001 0.001"/>
    </geometry>
    <material name="silver"/>
  </visual>
  <collision>
    <origin xyz="-0.289378 -0.06214 0.041845" rpy="0 0 0"/>
    <geometry>
      <mesh filename="file://$(find hexapod_description)/meshes/leg_5_femur_1.stl" scale="0.001 0.001 0.001"/>
    </geometry>
  </collision>
</link>

<link name="leg_5_tibia_1">
  <inertial>
    <origin xyz="0.0174817070554254 0.02824344164925982 -0.02485431833782275" rpy="0 0 0"/>
    <mass value="0.9074869947367368"/>
    <inertia ixx="0.002943" iyy="0.003179" izz="0.000408" ixy="3e-05" iyz="-4.2e-05" ixz="0.000741"/>
  </inertial>
  <visual>
    <origin xyz="-0.359145 -0.059902 -0.029763" rpy="0 0 0"/>
    <geometry>
      <mesh filename="file://$(find hexapod_description)/meshes/leg_5_tibia_1.stl" scale="0.001 0.001 0.001"/>
    </geometry>
    <material name="silver"/>
  </visual>
  <collision>
    <origin xyz="-0.359145 -0.059902 -0.029763" rpy="0 0 0"/>
    <geometry>
      <mesh filename="file://$(find hexapod_description)/meshes/leg_5_tibia_1.stl" scale="0.001 0.001 0.001"/>
    </geometry>
  </collision>
</link>

<link name="leg_6_coxa_1">
  <inertial>
    <origin xyz="0.02799749986364608 0.0031619781927097745 -0.05536647017049945" rpy="0 0 0"/>
    <mass value="1.0132520108724496"/>
    <inertia ixx="0.000828" iyy="0.001313" izz="0.001012" ixy="0.000138" iyz="-9.9e-05" ixz="0.000522"/>
  </inertial>
  <visual>
    <origin xyz="-0.216108 -0.226108 -0.040003" rpy="0 0 0"/>
    <geometry>
      <mesh filename="file://$(find hexapod_description)/meshes/leg_6_coxa_1.stl" scale="0.001 0.001 0.001"/>
    </geometry>
    <material name="gold"/>
  </visual>
  <collision>
    <origin xyz="-0.216108 -0.226108 -0.040003" rpy="0 0 0"/>
    <geometry>
      <mesh filename="file://$(find hexapod_description)/meshes/leg_6_coxa_1.stl" scale="0.001 0.001 0.001"/>
    </geometry>
  </collision>
</link>

<link name="leg_6_femur_1">
  <inertial>
    <origin xyz="0.036035245056249054 0.023753882387363978 0.035773547174522295" rpy="0 0 0"/>
    <mass value="0.22866968962750417"/>
    <inertia ixx="0.000318" iyy="0.000276" izz="0.00031" ixy="1e-06" iyz="1e-06" ixz="-0.000128"/>
  </inertial>
  <visual>
    <origin xyz="-0.283227 -0.192222 0.039665" rpy="0 0 0"/>
    <geometry>
      <mesh filename="file://$(find hexapod_description)/meshes/leg_6_femur_1.stl" scale="0.001 0.001 0.001"/>
    </geometry>
    <material name="silver"/>
  </visual>
  <collision>
    <origin xyz="-0.283227 -0.192222 0.039665" rpy="0 0 0"/>
    <geometry>
      <mesh filename="file://$(find hexapod_description)/meshes/leg_6_femur_1.stl" scale="0.001 0.001 0.001"/>
    </geometry>
  </collision>
</link>

<link name="leg_6_tibia_1">
  <inertial>
    <origin xyz="0.017481927655955798 0.02824373723592022 -0.024854413494753737" rpy="0 0 0"/>
    <mass value="0.9074869947367368"/>
    <inertia ixx="0.002943" iyy="0.003179" izz="0.000408" ixy="3e-05" iyz="-4.2e-05" ixz="0.000741"/>
  </inertial>
  <visual>
    <origin xyz="-0.352993 -0.189984 -0.031943" rpy="0 0 0"/>
    <geometry>
      <mesh filename="file://$(find hexapod_description)/meshes/leg_6_tibia_1.stl" scale="0.001 0.001 0.001"/>
    </geometry>
    <material name="silver"/>
  </visual>
  <collision>
    <origin xyz="-0.352993 -0.189984 -0.031943" rpy="0 0 0"/>
    <geometry>
      <mesh filename="file://$(find hexapod_description)/meshes/leg_6_tibia_1.stl" scale="0.001 0.001 0.001"/>
    </geometry>
  </collision>
</link>

<link name="leg_2_coxa_1">
  <inertial>
    <origin xyz="-0.028002513305086983 0.004227380638409481 -0.05523166050866125" rpy="0 0 0"/>
    <mass value="1.0126607300527286"/>
    <inertia ixx="0.000815" iyy="0.001315" izz="0.001011" ixy="-0.000122" iyz="-8.2e-05" ixz="-0.000522"/>
  </inertial>
  <visual>
    <origin xyz="0.009716 -0.099316 -0.038233" rpy="0 0 0"/>
    <geometry>
      <mesh filename="file://$(find hexapod_description)/meshes/leg_2_coxa_1.stl" scale="0.001 0.001 0.001"/>
    </geometry>
    <material name="gold"/>
  </visual>
  <collision>
    <origin xyz="0.009716 -0.099316 -0.038233" rpy="0 0 0"/>
    <geometry>
      <mesh filename="file://$(find hexapod_description)/meshes/leg_2_coxa_1.stl" scale="0.001 0.001 0.001"/>
    </geometry>
  </collision>
</link>

<link name="leg_2_femur_1">
  <inertial>
    <origin xyz="-0.0351899419407085 0.024819919769286505 0.035895211898902726" rpy="0 0 0"/>
    <mass value="0.22871574861196214"/>
    <inertia ixx="0.000319" iyy="0.000276" izz="0.00031" ixy="-2e-06" iyz="-2e-06" ixz="0.000128"/>
  </inertial>
  <visual>
    <origin xyz="0.077596 -0.067702 0.040978" rpy="0 0 0"/>
    <geometry>
      <mesh filename="file://$(find hexapod_description)/meshes/leg_2_femur_1.stl" scale="0.001 0.001 0.001"/>
    </geometry>
    <material name="silver"/>
  </visual>
  <collision>
    <origin xyz="0.077596 -0.067702 0.040978" rpy="0 0 0"/>
    <geometry>
      <mesh filename="file://$(find hexapod_description)/meshes/leg_2_femur_1.stl" scale="0.001 0.001 0.001"/>
    </geometry>
  </collision>
</link>

<link name="leg_2_tibia_1">
  <inertial>
    <origin xyz="-0.016642304592964313 0.028745590612428804 -0.02450393123674621" rpy="0 0 0"/>
    <mass value="0.9073984436402253"/>
    <inertia ixx="0.002924" iyy="0.003177" izz="0.000422" ixy="-2.3e-05" iyz="-1.9e-05" ixz="-0.000767"/>
  </inertial>
  <visual>
    <origin xyz="0.147152 -0.067535 -0.030868" rpy="0 0 0"/>
    <geometry>
      <mesh filename="file://$(find hexapod_description)/meshes/leg_2_tibia_1.stl" scale="0.001 0.001 0.001"/>
    </geometry>
    <material name="silver"/>
  </visual>
  <collision>
    <origin xyz="0.147152 -0.067535 -0.030868" rpy="0 0 0"/>
    <geometry>
      <mesh filename="file://$(find hexapod_description)/meshes/leg_2_tibia_1.stl" scale="0.001 0.001 0.001"/>
    </geometry>
  </collision>
</link>

<link name="leg_4_femur_1">
  <inertial>
    <origin xyz="0.03599324075088545 0.023816370449820927 0.03577397141224939" rpy="0 0 0"/>
    <mass value="0.22866968962750417"/>
    <inertia ixx="0.000318" iyy="0.000276" izz="0.00031" ixy="1e-06" iyz="1e-06" ixz="-0.000128"/>
  </inertial>
  <visual>
    <origin xyz="-0.279593 0.067598 0.043994" rpy="0 0 0"/>
    <geometry>
      <mesh filename="file://$(find hexapod_description)/meshes/leg_4_femur_1.stl" scale="0.001 0.001 0.001"/>
    </geometry>
    <material name="silver"/>
  </visual>
  <collision>
    <origin xyz="-0.279593 0.067598 0.043994" rpy="0 0 0"/>
    <geometry>
      <mesh filename="file://$(find hexapod_description)/meshes/leg_4_femur_1.stl" scale="0.001 0.001 0.001"/>
    </geometry>
  </collision>
</link>

<link name="leg_4_tibia_1">
  <inertial>
    <origin xyz="0.017433595987004558 0.028274562683989153 -0.024853491994180972" rpy="0 0 0"/>
    <mass value="0.9074869947367368"/>
    <inertia ixx="0.002943" iyy="0.003179" izz="0.000408" ixy="2.9e-05" iyz="-4e-05" ixz="0.000742"/>
  </inertial>
  <visual>
    <origin xyz="-0.349361 0.069715 -0.027615" rpy="0 0 0"/>
    <geometry>
      <mesh filename="file://$(find hexapod_description)/meshes/leg_4_tibia_1.stl" scale="0.001 0.001 0.001"/>
    </geometry>
    <material name="silver"/>
  </visual>
  <collision>
    <origin xyz="-0.349361 0.069715 -0.027615" rpy="0 0 0"/>
    <geometry>
      <mesh filename="file://$(find hexapod_description)/meshes/leg_4_tibia_1.stl" scale="0.001 0.001 0.001"/>
    </geometry>
  </collision>
</link>

<joint name="leg_1_coxa_joint" type="revolute">
  <origin xyz="-0.003565 -0.030766 0.036053" rpy="0 0 0"/>
  <parent link="base_link"/>
  <child link="leg_1_coxa_1"/>
  <axis xyz="-0.001529 0.016683 -0.99986"/>
  <limit effort="100" lower="-1.57" upper="1.57" velocity="100"/>
  <dynamics damping="10" friction="0.1"/>
</joint>

<joint name="leg_1_femur_joint" type="revolute">
  <origin xyz="-0.067837 -0.031701 -0.079213" rpy="0 0 0"/>
  <parent link="leg_1_coxa_1"/>
  <child link="leg_1_femur_1"/>
  <axis xyz="-0.013531 -0.99977 -0.016661"/>
  <limit effort="100" lower="-1.57" upper="1.57" velocity="100"/>
  <dynamics damping="10" friction="0.1"/>
</joint>

<joint name="leg_1_tibia_joint" type="revolute">
  <origin xyz="-0.069559 -0.000256 0.071844" rpy="0 0 0"/>
  <parent link="leg_1_femur_1"/>
  <child link="leg_1_tibia_1"/>
  <axis xyz="-0.013531 -0.99977 -0.016661"/>
  <limit effort="100" lower="-1.57" upper="1.57" velocity="100"/>
  <dynamics damping="10" friction="0.1"/>
</joint>

<joint name="leg_3_coxa_joint" type="revolute">
  <origin xyz="0.00013 0.229172 0.040385" rpy="0 0 0"/>
  <parent link="base_link"/>
  <child link="leg_3_coxa_1"/>
  <axis xyz="-0.001529 0.016683 -0.99986"/>
  <limit effort="100" lower="-1.57" upper="1.57" velocity="100"/>
  <dynamics damping="10" friction="0.1"/>
</joint>

<joint name="leg_3_femur_joint" type="revolute">
  <origin xyz="-0.067878 -0.031617 -0.079212" rpy="0 0 0"/>
  <parent link="leg_3_coxa_1"/>
  <child link="leg_3_femur_1"/>
  <axis xyz="-0.014767 -0.999752 -0.016659"/>
  <limit effort="100" lower="-1.57" upper="1.57" velocity="100"/>
  <dynamics damping="10" friction="0.1"/>
</joint>

<joint name="leg_3_tibia_joint" type="revolute">
  <origin xyz="-0.069549 -0.00017 0.071854" rpy="0 0 0"/>
  <parent link="leg_3_femur_1"/>
  <child link="leg_3_tibia_1"/>
  <axis xyz="-0.014767 -0.999752 -0.016659"/>
  <limit effort="100" lower="-1.57" upper="1.57" velocity="100"/>
  <dynamics damping="10" friction="0.1"/>
</joint>

<joint name="leg_4_coxa_joint" type="revolute">
  <origin xyz="0.212413 -0.03383 0.035672" rpy="0 0 0"/>
  <parent link="base_link"/>
  <child link="leg_4_coxa_1"/>
  <axis xyz="-0.001529 0.016683 -0.99986"/>
  <limit effort="100" lower="-1.57" upper="1.57" velocity="100"/>
  <dynamics damping="10" friction="0.1"/>
</joint>

<joint name="leg_5_coxa_joint" type="revolute">
  <origin xyz="0.22226 0.096026 0.037823" rpy="0 0 0"/>
  <parent link="base_link"/>
  <child link="leg_5_coxa_1"/>
  <axis xyz="-0.001529 0.016683 -0.99986"/>
  <limit effort="100" lower="-1.57" upper="1.57" velocity="100"/>
  <dynamics damping="10" friction="0.1"/>
</joint>

<joint name="leg_5_femur_joint" type="revolute">
  <origin xyz="0.067118 -0.033886 -0.079668" rpy="0 0 0"/>
  <parent link="leg_5_coxa_1"/>
  <child link="leg_5_femur_1"/>
  <axis xyz="-0.014972 -0.999749 -0.016658"/>
  <limit effort="100" lower="-1.57" upper="1.57" velocity="100"/>
  <dynamics damping="10" friction="0.1"/>
</joint>

<joint name="leg_5_tibia_joint" type="revolute">
  <origin xyz="0.069767 -0.002238 0.071608" rpy="0 0 0"/>
  <parent link="leg_5_femur_1"/>
  <child link="leg_5_tibia_1"/>
  <axis xyz="0.014972 0.999749 0.016658"/>
  <limit effort="100" lower="-1.57" upper="1.57" velocity="100"/>
  <dynamics damping="10" friction="0.1"/>
</joint>

<joint name="leg_6_coxa_joint" type="revolute">
  <origin xyz="0.216108 0.226108 0.040003" rpy="0 0 0"/>
  <parent link="base_link"/>
  <child link="leg_6_coxa_1"/>
  <axis xyz="-0.001529 0.016683 -0.99986"/>
  <limit effort="100" lower="-1.57" upper="1.57" velocity="100"/>
  <dynamics damping="10" friction="0.1"/>
</joint>

<joint name="leg_6_femur_joint" type="revolute">
  <origin xyz="0.067119 -0.033886 -0.079668" rpy="0 0 0"/>
  <parent link="leg_6_coxa_1"/>
  <child link="leg_6_femur_1"/>
  <axis xyz="-0.014972 -0.999749 -0.016658"/>
  <limit effort="100" lower="-1.57" upper="1.57" velocity="100"/>
  <dynamics damping="10" friction="0.1"/>
</joint>

<joint name="leg_6_tibia_joint" type="revolute">
  <origin xyz="0.069766 -0.002238 0.071608" rpy="0 0 0"/>
  <parent link="leg_6_femur_1"/>
  <child link="leg_6_tibia_1"/>
  <axis xyz="0.014972 0.999749 0.016658"/>
  <limit effort="100" lower="-1.57" upper="1.57" velocity="100"/>
  <dynamics damping="10" friction="0.1"/>
</joint>

<joint name="leg_2_coxa_joint" type="revolute">
  <origin xyz="-0.009716 0.099316 0.038233" rpy="0 0 0"/>
  <parent link="base_link"/>
  <child link="leg_2_coxa_1"/>
  <axis xyz="-0.001529 0.016683 -0.99986"/>
  <limit effort="100" lower="-1.57" upper="1.57" velocity="100"/>
  <dynamics damping="10" friction="0.1"/>
</joint>

<joint name="leg_2_femur_joint" type="revolute">
  <origin xyz="-0.06788 -0.031614 -0.079211" rpy="0 0 0"/>
  <parent link="leg_2_coxa_1"/>
  <child link="leg_2_femur_1"/>
  <axis xyz="-0.014806 -0.999752 -0.016659"/>
  <limit effort="100" lower="-1.57" upper="1.57" velocity="100"/>
  <dynamics damping="10" friction="0.1"/>
</joint>

<joint name="leg_2_tibia_joint" type="revolute">
  <origin xyz="-0.069556 -0.000167 0.071846" rpy="0 0 0"/>
  <parent link="leg_2_femur_1"/>
  <child link="leg_2_tibia_1"/>
  <axis xyz="-0.014806 -0.999752 -0.016659"/>
  <limit effort="100" lower="-1.57" upper="1.57" velocity="100"/>
  <dynamics damping="10" friction="0.1"/>
</joint>

<joint name="leg_4_femur_joint" type="revolute">
  <origin xyz="0.06718 -0.033768 -0.079666" rpy="0 0 0"/>
  <parent link="leg_4_coxa_1"/>
  <child link="leg_4_femur_1"/>
  <axis xyz="-0.013227 -0.999774 -0.016662"/>
  <limit effort="100" lower="-1.57" upper="1.57" velocity="100"/>
  <dynamics damping="10" friction="0.1"/>
</joint>

<joint name="leg_4_tibia_joint" type="revolute">
  <origin xyz="0.069768 -0.002117 0.071609" rpy="0 0 0"/>
  <parent link="leg_4_femur_1"/>
  <child link="leg_4_tibia_1"/>
  <axis xyz="0.013227 0.999774 0.016662"/>
  <limit effort="100" lower="-1.57" upper="1.57" velocity="100"/>
  <dynamics damping="10" friction="0.1"/>
</joint>

</robot>
