<?xml version="1.0" ?>
<robot name="hexapod" xmlns:xacro="http://www.ros.org/wiki/xacro">

<xacro:include filename="$(find hexapod_description)/urdf/materials.xacro" />
<xacro:include filename="$(find hexapod_description)/urdf/hexapod.trans" />
<xacro:include filename="$(find hexapod_description)/urdf/hexapod.gazebo" />
<link name="base_link">
  <inertial>
    <origin xyz="0.1000352418955988 0.06495559041692857 0.006960329203092366" rpy="0 0 0"/>
    <mass value="14.09466584247892"/>
    <inertia ixx="0.167546" iyy="0.075339" izz="0.199615" ixy="-0.012339" iyz="0.003184" ixz="-0.003868"/>
  </inertial>
  <visual>
    <origin xyz="0 0 0" rpy="0 0 0"/>
    <geometry>
      <mesh filename="file://$(find hexapod_description)/meshes/base_link.stl" scale="0.001 0.001 0.001"/>
    </geometry>
    <material name="silver"/>
  </visual>
  <collision>
    <origin xyz="0 0 0" rpy="0 0 0"/>
    <geometry>
      <mesh filename="file://$(find hexapod_description)/meshes/base_link.stl" scale="0.001 0.001 0.001"/>
    </geometry>
  </collision>
</link>

<link name="leg_1_link_2_1">
  <inertial>
    <origin xyz="-0.020798247907869903 -0.003004122621169035 -0.05840364105605461" rpy="0 0 0"/>
    <mass value="1.012661950148346"/>
    <inertia ixx="0.001014" iyy="0.001236" izz="0.000891" ixy="-0.000197" iyz="-0.00022" ixz="-0.000489"/>
  </inertial>
  <visual>
    <origin xyz="0.031628 0.00646 -0.021757" rpy="0 0 0"/>
    <geometry>
      <mesh filename="file://$(find hexapod_description)/meshes/leg_1_link_2_1.stl" scale="0.001 0.001 0.001"/>
    </geometry>
    <material name="silver"/>
  </visual>
  <collision>
    <origin xyz="0.031628 0.00646 -0.021757" rpy="0 0 0"/>
    <geometry>
      <mesh filename="file://$(find hexapod_description)/meshes/leg_1_link_2_1.stl" scale="0.001 0.001 0.001"/>
    </geometry>
  </collision>
</link>

<link name="leg_1_link_3_1">
  <inertial>
    <origin xyz="-0.05232794213563882 0.015850438170881664 0.012387465467738626" rpy="0 0 0"/>
    <mass value="0.22871600239093776"/>
    <inertia ixx="0.000208" iyy="0.000275" izz="0.000422" ixy="-1e-05" iyz="1.8e-05" ixz="6.7e-05"/>
  </inertial>
  <visual>
    <origin xyz="0.080903 0.053284 0.063455" rpy="0 0 0"/>
    <geometry>
      <mesh filename="file://$(find hexapod_description)/meshes/leg_1_link_3_1.stl" scale="0.001 0.001 0.001"/>
    </geometry>
    <material name="silver"/>
  </visual>
  <collision>
    <origin xyz="0.080903 0.053284 0.063455" rpy="0 0 0"/>
    <geometry>
      <mesh filename="file://$(find hexapod_description)/meshes/leg_1_link_3_1.stl" scale="0.001 0.001 0.001"/>
    </geometry>
  </collision>
</link>

<link name="leg_1_link_1_1">
  <inertial>
    <origin xyz="-0.024118708207036738 0.023198280722906535 -0.02416394528421939" rpy="0 0 0"/>
    <mass value="0.907399585528797"/>
    <inertia ixx="0.0028" iyy="0.003123" izz="0.0006" ixy="-0.00015" iyz="-0.00034" ixz="-0.000941"/>
  </inertial>
  <visual>
    <origin xyz="0.175395 0.070243 0.035462" rpy="0 0 0"/>
    <geometry>
      <mesh filename="file://$(find hexapod_description)/meshes/leg_1_link_1_1.stl" scale="0.001 0.001 0.001"/>
    </geometry>
    <material name="silver"/>
  </visual>
  <collision>
    <origin xyz="0.175395 0.070243 0.035462" rpy="0 0 0"/>
    <geometry>
      <mesh filename="file://$(find hexapod_description)/meshes/leg_1_link_1_1.stl" scale="0.001 0.001 0.001"/>
    </geometry>
  </collision>
</link>

<link name="leg_3_link_3_1">
  <inertial>
    <origin xyz="-0.01471532830032863 0.017066498243044487 -0.05783367655412228" rpy="0 0 0"/>
    <mass value="1.0126620006859057"/>
    <inertia ixx="0.000964" iyy="0.001294" izz="0.000883" ixy="0.000135" iyz="0.000218" ixz="-0.000494"/>
  </inertial>
  <visual>
    <origin xyz="-0.02145 -0.24803 -0.025922" rpy="0 0 0"/>
    <geometry>
      <mesh filename="file://$(find hexapod_description)/meshes/leg_3_link_3_1.stl" scale="0.001 0.001 0.001"/>
    </geometry>
    <material name="silver"/>
  </visual>
  <collision>
    <origin xyz="-0.02145 -0.24803 -0.025922" rpy="0 0 0"/>
    <geometry>
      <mesh filename="file://$(find hexapod_description)/meshes/leg_3_link_3_1.stl" scale="0.001 0.001 0.001"/>
    </geometry>
  </collision>
</link>

<link name="leg_3_link_2_1">
  <inertial>
    <origin xyz="-0.02490321172110873 0.04393892851157011 0.024331856966839732" rpy="0 0 0"/>
    <mass value="0.2287158182027981"/>
    <inertia ixx="0.000248" iyy="0.000272" izz="0.000385" ixy="1.3e-05" iyz="-6.3e-05" ixz="8.6e-05"/>
  </inertial>
  <visual>
    <origin xyz="0.042897 -0.255314 0.061759" rpy="0 0 0"/>
    <geometry>
      <mesh filename="file://$(find hexapod_description)/meshes/leg_3_link_2_1.stl" scale="0.001 0.001 0.001"/>
    </geometry>
    <material name="silver"/>
  </visual>
  <collision>
    <origin xyz="0.042897 -0.255314 0.061759" rpy="0 0 0"/>
    <geometry>
      <mesh filename="file://$(find hexapod_description)/meshes/leg_3_link_2_1.stl" scale="0.001 0.001 0.001"/>
    </geometry>
  </collision>
</link>

<link name="leg_3_link_1_1">
  <inertial>
    <origin xyz="0.008717952333481188 0.029799584273488944 -0.027197642277439673" rpy="0 0 0"/>
    <mass value="0.9073986789846695"/>
    <inertia ixx="0.00313" iyy="0.003181" izz="0.000211" ixy="8e-06" iyz="3.3e-05" ixz="0.000122"/>
  </inertial>
  <visual>
    <origin xyz="0.11862 -0.300684 0.014775" rpy="0 0 0"/>
    <geometry>
      <mesh filename="file://$(find hexapod_description)/meshes/leg_3_link_1_1.stl" scale="0.001 0.001 0.001"/>
    </geometry>
    <material name="silver"/>
  </visual>
  <collision>
    <origin xyz="0.11862 -0.300684 0.014775" rpy="0 0 0"/>
    <geometry>
      <mesh filename="file://$(find hexapod_description)/meshes/leg_3_link_1_1.stl" scale="0.001 0.001 0.001"/>
    </geometry>
  </collision>
</link>

<link name="leg_4_link_3_1">
  <inertial>
    <origin xyz="0.03474109636392422 -0.003845593381223762 -0.051356732674382274" rpy="0 0 0"/>
    <mass value="1.0132520108724496"/>
    <inertia ixx="0.000782" iyy="0.001231" izz="0.001141" ixy="0.000257" iyz="-0.000175" ixz="0.000456"/>
  </inertial>
  <visual>
    <origin xyz="-0.178057 0.050638 -0.048896" rpy="0 0 0"/>
    <geometry>
      <mesh filename="file://$(find hexapod_description)/meshes/leg_4_link_3_1.stl" scale="0.001 0.001 0.001"/>
    </geometry>
    <material name="silver"/>
  </visual>
  <collision>
    <origin xyz="-0.178057 0.050638 -0.048896" rpy="0 0 0"/>
    <geometry>
      <mesh filename="file://$(find hexapod_description)/meshes/leg_4_link_3_1.stl" scale="0.001 0.001 0.001"/>
    </geometry>
  </collision>
</link>

<link name="leg_4_link_2_1">
  <inertial>
    <origin xyz="-0.010888666203385994 0.026973289808990053 0.04744870332220183" rpy="0 0 0"/>
    <mass value="0.2286696896275042"/>
    <inertia ixx="0.00041" iyy="0.000283" izz="0.000211" ixy="-3e-05" iyz="-1.5e-05" ixz="7.4e-05"/>
  </inertial>
  <visual>
    <origin xyz="-0.24657 0.099091 0.02152" rpy="0 0 0"/>
    <geometry>
      <mesh filename="file://$(find hexapod_description)/meshes/leg_4_link_2_1.stl" scale="0.001 0.001 0.001"/>
    </geometry>
    <material name="silver"/>
  </visual>
  <collision>
    <origin xyz="-0.24657 0.099091 0.02152" rpy="0 0 0"/>
    <geometry>
      <mesh filename="file://$(find hexapod_description)/meshes/leg_4_link_2_1.stl" scale="0.001 0.001 0.001"/>
    </geometry>
  </collision>
</link>

<link name="leg_4_link_1_1">
  <inertial>
    <origin xyz="0.02172755655481845 0.024507117043729182 -0.025464522928266398" rpy="0 0 0"/>
    <mass value="0.9074869947367368"/>
    <inertia ixx="0.003012" iyy="0.003161" izz="0.000357" ixy="6.1e-05" iyz="-0.000166" ixz="0.000626"/>
  </inertial>
  <visual>
    <origin xyz="-0.215846 0.094134 -0.073515" rpy="0 0 0"/>
    <geometry>
      <mesh filename="file://$(find hexapod_description)/meshes/leg_4_link_1_1.stl" scale="0.001 0.001 0.001"/>
    </geometry>
    <material name="silver"/>
  </visual>
  <collision>
    <origin xyz="-0.215846 0.094134 -0.073515" rpy="0 0 0"/>
    <geometry>
      <mesh filename="file://$(find hexapod_description)/meshes/leg_4_link_1_1.stl" scale="0.001 0.001 0.001"/>
    </geometry>
  </collision>
</link>

<link name="leg_5_link_3_1">
  <inertial>
    <origin xyz="0.03431863832487392 -0.006415093388469753 -0.05138466470919113" rpy="0 0 0"/>
    <mass value="1.0132520108724496"/>
    <inertia ixx="0.000831" iyy="0.001185" izz="0.001137" ixy="0.000289" iyz="-0.000215" ixz="0.000441"/>
  </inertial>
  <visual>
    <origin xyz="-0.212362 -0.074971 -0.051984" rpy="0 0 0"/>
    <geometry>
      <mesh filename="file://$(find hexapod_description)/meshes/leg_5_link_3_1.stl" scale="0.001 0.001 0.001"/>
    </geometry>
    <material name="silver"/>
  </visual>
  <collision>
    <origin xyz="-0.212362 -0.074971 -0.051984" rpy="0 0 0"/>
    <geometry>
      <mesh filename="file://$(find hexapod_description)/meshes/leg_5_link_3_1.stl" scale="0.001 0.001 0.001"/>
    </geometry>
  </collision>
</link>

<link name="leg_5_llink_2_1">
  <inertial>
    <origin xyz="0.018771123341369156 0.018755066663032692 0.04938055386133791" rpy="0 0 0"/>
    <mass value="0.2286696896275042"/>
    <inertia ixx="0.000416" iyy="0.000289" izz="0.000199" ixy="-4.2e-05" iyz="1.9e-05" ixz="-5.3e-05"/>
  </inertial>
  <visual>
    <origin xyz="-0.276253 -0.021267 0.018967" rpy="0 0 0"/>
    <geometry>
      <mesh filename="file://$(find hexapod_description)/meshes/leg_5_llink_2_1.stl" scale="0.001 0.001 0.001"/>
    </geometry>
    <material name="silver"/>
  </visual>
  <collision>
    <origin xyz="-0.276253 -0.021267 0.018967" rpy="0 0 0"/>
    <geometry>
      <mesh filename="file://$(find hexapod_description)/meshes/leg_5_llink_2_1.stl" scale="0.001 0.001 0.001"/>
    </geometry>
  </collision>
</link>

<link name="leg_5_link_1_1">
  <inertial>
    <origin xyz="0.02550183545753798 0.022180183688185383 -0.02405814830958873" rpy="0 0 0"/>
    <mass value="0.9074869947367368"/>
    <inertia ixx="0.002936" iyy="0.003145" izz="0.000449" ixy="9.4e-05" iyz="-0.00024" ixz="0.000773"/>
  </inertial>
  <visual>
    <origin xyz="-0.297249 -0.011829 -0.078348" rpy="0 0 0"/>
    <geometry>
      <mesh filename="file://$(find hexapod_description)/meshes/leg_5_link_1_1.stl" scale="0.001 0.001 0.001"/>
    </geometry>
    <material name="silver"/>
  </visual>
  <collision>
    <origin xyz="-0.297249 -0.011829 -0.078348" rpy="0 0 0"/>
    <geometry>
      <mesh filename="file://$(find hexapod_description)/meshes/leg_5_link_1_1.stl" scale="0.001 0.001 0.001"/>
    </geometry>
  </collision>
</link>

<link name="leg_6_link_3_1">
  <inertial>
    <origin xyz="0.03478752240465702 -0.0034309973765440926 -0.05135500529375246" rpy="0 0 0"/>
    <mass value="1.0132520108724496"/>
    <inertia ixx="0.000774" iyy="0.001238" izz="0.001142" ixy="0.000252" iyz="-0.000168" ixz="0.000458"/>
  </inertial>
  <visual>
    <origin xyz="-0.231135 -0.203852 -0.053061" rpy="0 0 0"/>
    <geometry>
      <mesh filename="file://$(find hexapod_description)/meshes/leg_6_link_3_1.stl" scale="0.001 0.001 0.001"/>
    </geometry>
    <material name="silver"/>
  </visual>
  <collision>
    <origin xyz="-0.231135 -0.203852 -0.053061" rpy="0 0 0"/>
    <geometry>
      <mesh filename="file://$(find hexapod_description)/meshes/leg_6_link_3_1.stl" scale="0.001 0.001 0.001"/>
    </geometry>
  </collision>
</link>

<link name="leg_6_link_2_1">
  <inertial>
    <origin xyz="0.03849750463385049 0.017157271320907497 0.03696038927730658" rpy="0 0 0"/>
    <mass value="0.2286696896275042"/>
    <inertia ixx="0.000325" iyy="0.000278" izz="0.000301" ixy="-8e-06" iyz="2.5e-05" ixz="-0.000125"/>
  </inertial>
  <visual>
    <origin xyz="-0.300343 -0.156279 0.017275" rpy="0 0 0"/>
    <geometry>
      <mesh filename="file://$(find hexapod_description)/meshes/leg_6_link_2_1.stl" scale="0.001 0.001 0.001"/>
    </geometry>
    <material name="silver"/>
  </visual>
  <collision>
    <origin xyz="-0.300343 -0.156279 0.017275" rpy="0 0 0"/>
    <geometry>
      <mesh filename="file://$(find hexapod_description)/meshes/leg_6_link_2_1.stl" scale="0.001 0.001 0.001"/>
    </geometry>
  </collision>
</link>

<link name="leg_6_link_1_1">
  <inertial>
    <origin xyz="0.02586216823859211 0.02382740021676627 -0.022010668931323946" rpy="0 0 0"/>
    <mass value="0.9074869947367368"/>
    <inertia ixx="0.002693" iyy="0.003147" izz="0.00069" ixy="0.00013" iyz="-0.000245" ixz="0.001062"/>
  </inertial>
  <visual>
    <origin xyz="-0.36607 -0.142086 -0.056742" rpy="0 0 0"/>
    <geometry>
      <mesh filename="file://$(find hexapod_description)/meshes/leg_6_link_1_1.stl" scale="0.001 0.001 0.001"/>
    </geometry>
    <material name="silver"/>
  </visual>
  <collision>
    <origin xyz="-0.36607 -0.142086 -0.056742" rpy="0 0 0"/>
    <geometry>
      <mesh filename="file://$(find hexapod_description)/meshes/leg_6_link_1_1.stl" scale="0.001 0.001 0.001"/>
    </geometry>
  </collision>
</link>

<link name="leg_2_link_3__1__1">
  <inertial>
    <origin xyz="-0.0204324626555867 0.004535002979926123 -0.058433485854018384" rpy="0 0 0"/>
    <mass value="1.0126607300527286"/>
    <inertia ixx="0.000937" iyy="0.001326" izz="0.000878" ixy="-9.5e-05" iyz="-6.9e-05" ixz="-0.000533"/>
  </inertial>
  <visual>
    <origin xyz="0.012855 -0.122421 -0.022834" rpy="0 0 0"/>
    <geometry>
      <mesh filename="file://$(find hexapod_description)/meshes/leg_2_link_3__1__1.stl" scale="0.001 0.001 0.001"/>
    </geometry>
    <material name="silver"/>
  </visual>
  <collision>
    <origin xyz="0.012855 -0.122421 -0.022834" rpy="0 0 0"/>
    <geometry>
      <mesh filename="file://$(find hexapod_description)/meshes/leg_2_link_3__1__1.stl" scale="0.001 0.001 0.001"/>
    </geometry>
  </collision>
</link>

<link name="leg_2_link_2_1">
  <inertial>
    <origin xyz="-0.04728937759402714 0.028753242764041703 0.008935509645913484" rpy="0 0 0"/>
    <mass value="0.22871574861196214"/>
    <inertia ixx="0.000197" iyy="0.000276" izz="0.000432" ixy="7e-06" iyz="-4e-06" ixz="4.9e-05"/>
  </inertial>
  <visual>
    <origin xyz="0.072124 -0.093122 0.063828" rpy="0 0 0"/>
    <geometry>
      <mesh filename="file://$(find hexapod_description)/meshes/leg_2_link_2_1.stl" scale="0.001 0.001 0.001"/>
    </geometry>
    <material name="silver"/>
  </visual>
  <collision>
    <origin xyz="0.072124 -0.093122 0.063828" rpy="0 0 0"/>
    <geometry>
      <mesh filename="file://$(find hexapod_description)/meshes/leg_2_link_2_1.stl" scale="0.001 0.001 0.001"/>
    </geometry>
  </collision>
</link>

<link name="leg_2_link_1_1">
  <inertial>
    <origin xyz="0.00945298222541896 0.027417343905499214 0.029370612679365103" rpy="0 0 0"/>
    <mass value="0.9073984436402253"/>
    <inertia ixx="0.003123" iyy="0.003172" izz="0.000228" ixy="1.4e-05" iyz="6.6e-05" ixz="0.000248"/>
  </inertial>
  <visual>
    <origin xyz="0.169894 -0.100943 0.04434" rpy="0 0 0"/>
    <geometry>
      <mesh filename="file://$(find hexapod_description)/meshes/leg_2_link_1_1.stl" scale="0.001 0.001 0.001"/>
    </geometry>
    <material name="silver"/>
  </visual>
  <collision>
    <origin xyz="0.169894 -0.100943 0.04434" rpy="0 0 0"/>
    <geometry>
      <mesh filename="file://$(find hexapod_description)/meshes/leg_2_link_1_1.stl" scale="0.001 0.001 0.001"/>
    </geometry>
  </collision>
</link>

<joint name="Revolute 63" type="revolute">
  <origin xyz="-0.031628 -0.00646 0.021757" rpy="0 0 0"/>
  <parent link="base_link"/>
  <child link="leg_1_link_2_1"/>
  <axis xyz="0.126261 -0.010099 -0.991946"/>
  <limit effort="100" lower="-1.57" upper="1.57" velocity="100"/>
  <dynamics damping="10" friction="0.1"/>
</joint>

<joint name="Revolute 64" type="revolute">
  <origin xyz="-0.049275 -0.046824 -0.085212" rpy="0 0 0"/>
  <parent link="leg_1_link_2_1"/>
  <child link="leg_1_link_3_1"/>
  <axis xyz="0.186207 -0.981932 0.033699"/>
  <limit effort="100" lower="-1.57" upper="1.57" velocity="100"/>
  <dynamics damping="10" friction="0.1"/>
</joint>

<joint name="Revolute 65" type="revolute">
  <origin xyz="-0.094492 -0.016959 0.027993" rpy="0 0 0"/>
  <parent link="leg_1_link_3_1"/>
  <child link="leg_1_link_1_1"/>
  <axis xyz="0.186207 -0.981932 0.033699"/>
  <limit effort="100" lower="-1.57" upper="1.57" velocity="100"/>
  <dynamics damping="10" friction="0.1"/>
</joint>

<joint name="Revolute 69" type="revolute">
  <origin xyz="0.02145 0.24803 0.025922" rpy="0 0 0"/>
  <parent link="base_link"/>
  <child link="leg_3_link_3_1"/>
  <axis xyz="0.126261 -0.010099 -0.991946"/>
  <limit effort="100" lower="-1.57" upper="1.57" velocity="100"/>
  <dynamics damping="10" friction="0.1"/>
</joint>

<joint name="Revolute 70" type="revolute">
  <origin xyz="-0.064347 0.007284 -0.087681" rpy="0 0 0"/>
  <parent link="leg_3_link_3_1"/>
  <child link="leg_3_link_2_1"/>
  <axis xyz="-0.540263 -0.839339 -0.060222"/>
  <limit effort="100" lower="-1.57" upper="1.57" velocity="100"/>
  <dynamics damping="10" friction="0.1"/>
</joint>

<joint name="Revolute 71" type="revolute">
  <origin xyz="-0.075723 0.04537 0.046984" rpy="0 0 0"/>
  <parent link="leg_3_link_2_1"/>
  <child link="leg_3_link_1_1"/>
  <axis xyz="-0.540263 -0.839339 -0.060222"/>
  <limit effort="100" lower="-1.57" upper="1.57" velocity="100"/>
  <dynamics damping="10" friction="0.1"/>
</joint>

<joint name="Revolute 72" type="revolute">
  <origin xyz="0.178057 -0.050638 0.048896" rpy="0 0 0"/>
  <parent link="base_link"/>
  <child link="leg_4_link_3_1"/>
  <axis xyz="0.126261 -0.010099 -0.991946"/>
  <limit effort="100" lower="-1.57" upper="1.57" velocity="100"/>
  <dynamics damping="10" friction="0.1"/>
</joint>

<joint name="Revolute 73" type="revolute">
  <origin xyz="0.068513 -0.048453 -0.070416" rpy="0 0 0"/>
  <parent link="leg_4_link_3_1"/>
  <child link="leg_4_link_2_1"/>
  <axis xyz="-0.209414 -0.977684 -0.016701"/>
  <limit effort="100" lower="-1.57" upper="1.57" velocity="100"/>
  <dynamics damping="10" friction="0.1"/>
</joint>

<joint name="Revolute 74" type="revolute">
  <origin xyz="-0.030724 0.004957 0.095035" rpy="0 0 0"/>
  <parent link="leg_4_link_2_1"/>
  <child link="leg_4_link_1_1"/>
  <axis xyz="0.209414 0.977684 0.016701"/>
  <limit effort="100" lower="-1.57" upper="1.57" velocity="100"/>
  <dynamics damping="10" friction="0.1"/>
</joint>

<joint name="Revolute 75" type="revolute">
  <origin xyz="0.212362 0.074971 0.051984" rpy="0 0 0"/>
  <parent link="base_link"/>
  <child link="leg_5_link_3_1"/>
  <axis xyz="0.126261 -0.010099 -0.991946"/>
  <limit effort="100" lower="-1.57" upper="1.57" velocity="100"/>
  <dynamics damping="10" friction="0.1"/>
</joint>

<joint name="Revolute 76" type="revolute">
  <origin xyz="0.063891 -0.053704 -0.070951" rpy="0 0 0"/>
  <parent link="leg_5_link_3_1"/>
  <child link="leg_5_llink_2_1"/>
  <axis xyz="-0.298057 -0.954131 -0.028224"/>
  <limit effort="100" lower="-1.57" upper="1.57" velocity="100"/>
  <dynamics damping="10" friction="0.1"/>
</joint>

<joint name="Revolute 77" type="revolute">
  <origin xyz="0.020996 -0.009438 0.097315" rpy="0 0 0"/>
  <parent link="leg_5_llink_2_1"/>
  <child link="leg_5_link_1_1"/>
  <axis xyz="0.298057 0.954131 0.028224"/>
  <limit effort="100" lower="-1.57" upper="1.57" velocity="100"/>
  <dynamics damping="10" friction="0.1"/>
</joint>

<joint name="Revolute 78" type="revolute">
  <origin xyz="0.231135 0.203852 0.053061" rpy="0 0 0"/>
  <parent link="base_link"/>
  <child link="leg_6_link_3_1"/>
  <axis xyz="0.126261 -0.010099 -0.991946"/>
  <limit effort="100" lower="-1.57" upper="1.57" velocity="100"/>
  <dynamics damping="10" friction="0.1"/>
</joint>

<joint name="Revolute 79" type="revolute">
  <origin xyz="0.069208 -0.047573 -0.070336" rpy="0 0 0"/>
  <parent link="leg_6_link_3_1"/>
  <child link="leg_6_link_2_1"/>
  <axis xyz="-0.195044 -0.980682 -0.014842"/>
  <limit effort="100" lower="-1.57" upper="1.57" velocity="100"/>
  <dynamics damping="10" friction="0.1"/>
</joint>

<joint name="Revolute 80" type="revolute">
  <origin xyz="0.065727 -0.014193 0.074017" rpy="0 0 0"/>
  <parent link="leg_6_link_2_1"/>
  <child link="leg_6_link_1_1"/>
  <axis xyz="0.195044 0.980682 0.014842"/>
  <limit effort="100" lower="-1.57" upper="1.57" velocity="100"/>
  <dynamics damping="10" friction="0.1"/>
</joint>

<joint name="Revolute 81" type="revolute">
  <origin xyz="-0.012855 0.122421 0.022834" rpy="0 0 0"/>
  <parent link="base_link"/>
  <child link="leg_2_link_3__1__1"/>
  <axis xyz="0.126261 -0.010099 -0.991946"/>
  <limit effort="100" lower="-1.57" upper="1.57" velocity="100"/>
  <dynamics damping="10" friction="0.1"/>
</joint>

<joint name="Revolute 82" type="revolute">
  <origin xyz="-0.059269 -0.029299 -0.086662" rpy="0 0 0"/>
  <parent link="leg_2_link_3__1__1"/>
  <child link="leg_2_link_2_1"/>
  <axis xyz="-0.079733 -0.996816 0.0"/>
  <limit effort="100" lower="-1.57" upper="1.57" velocity="100"/>
  <dynamics damping="10" friction="0.1"/>
</joint>

<joint name="Revolute 83" type="revolute">
  <origin xyz="-0.09777 0.007821 0.019488" rpy="0 0 0"/>
  <parent link="leg_2_link_2_1"/>
  <child link="leg_2_link_1_1"/>
  <axis xyz="-0.079733 -0.996816 0.0"/>
  <limit effort="100" lower="-1.57" upper="1.57" velocity="100"/>
  <dynamics damping="10" friction="0.1"/>
</joint>

</robot>
