<?xml version="1.0" ?>
<robot name="hexapod" xmlns:xacro="http://www.ros.org/wiki/xacro">

<xacro:include filename="$(find hexapod_description)/urdf/materials.xacro" />
<xacro:include filename="$(find hexapod_description)/urdf/hexapod.trans" />
<xacro:include filename="$(find hexapod_description)/urdf/hexapod.gazebo" />
<link name="base_link">
  <inertial>
    <origin xyz="0.10909777793044037 0.06468612005136756 0.006889314215312581" rpy="0 0 0"/>
    <mass value="14.09466584247892"/>
    <inertia ixx="0.168182" iyy="0.074083" izz="0.200235" ixy="0.006215" iyz="0.001309" ixz="-0.000356"/>
  </inertial>
  <visual>
    <origin xyz="0 0 0" rpy="0 0 0"/>
    <geometry>
      <mesh filename="file://$(find hexapod_description)/meshes/base_link.stl" scale="0.001 0.001 0.001"/>
    </geometry>
    <material name="silver"/>
  </visual>
  <collision>
    <origin xyz="0 0 0" rpy="0 0 0"/>
    <geometry>
      <mesh filename="file://$(find hexapod_description)/meshes/base_link.stl" scale="0.001 0.001 0.001"/>
    </geometry>
  </collision>
</link>

<link name="leg_1_link_2_1">
  <inertial>
    <origin xyz="-0.02800590467788834 0.004191461427254562 -0.05523214859518318" rpy="0 0 0"/>
    <mass value="1.012661950148346"/>
    <inertia ixx="0.000816" iyy="0.001315" izz="0.00101" ixy="-0.000122" iyz="-8.3e-05" ixz="-0.000522"/>
  </inertial>
  <visual>
    <origin xyz="0.003565 0.030766 -0.036053" rpy="0 0 0"/>
    <geometry>
      <mesh filename="file://$(find hexapod_description)/meshes/leg_1_link_2_1.stl" scale="0.001 0.001 0.001"/>
    </geometry>
    <material name="silver"/>
  </visual>
  <collision>
    <origin xyz="0.003565 0.030766 -0.036053" rpy="0 0 0"/>
    <geometry>
      <mesh filename="file://$(find hexapod_description)/meshes/leg_1_link_2_1.stl" scale="0.001 0.001 0.001"/>
    </geometry>
  </collision>
</link>

<link name="leg_1_link_3_1">
  <inertial>
    <origin xyz="-0.036766491881322055 0.024823115706118865 0.034277514263341684" rpy="0 0 0"/>
    <mass value="0.22871600239093776"/>
    <inertia ixx="0.000307" iyy="0.000276" izz="0.000321" ixy="-2e-06" iyz="-2e-06" ixz="0.000128"/>
  </inertial>
  <visual>
    <origin xyz="0.071402 0.062467 0.04316" rpy="0 0 0"/>
    <geometry>
      <mesh filename="file://$(find hexapod_description)/meshes/leg_1_link_3_1.stl" scale="0.001 0.001 0.001"/>
    </geometry>
    <material name="silver"/>
  </visual>
  <collision>
    <origin xyz="0.071402 0.062467 0.04316" rpy="0 0 0"/>
    <geometry>
      <mesh filename="file://$(find hexapod_description)/meshes/leg_1_link_3_1.stl" scale="0.001 0.001 0.001"/>
    </geometry>
  </collision>
</link>

<link name="leg_1_link_1_1">
  <inertial>
    <origin xyz="-0.01779410893760297 0.028725816249512953 -0.02370507712814386" rpy="0 0 0"/>
    <mass value="0.907399585528797"/>
    <inertia ixx="0.002849" iyy="0.003176" izz="0.000497" ixy="-2.4e-05" iyz="-1.8e-05" ixz="-0.000878"/>
  </inertial>
  <visual>
    <origin xyz="0.144088 0.062627 -0.025519" rpy="0 0 0"/>
    <geometry>
      <mesh filename="file://$(find hexapod_description)/meshes/leg_1_link_1_1.stl" scale="0.001 0.001 0.001"/>
    </geometry>
    <material name="silver"/>
  </visual>
  <collision>
    <origin xyz="0.144088 0.062627 -0.025519" rpy="0 0 0"/>
    <geometry>
      <mesh filename="file://$(find hexapod_description)/meshes/leg_1_link_1_1.stl" scale="0.001 0.001 0.001"/>
    </geometry>
  </collision>
</link>

<link name="leg_3_link_3_1">
  <inertial>
    <origin xyz="-0.02800203130695705 0.004225621248029748 -0.05523202595087612" rpy="0 0 0"/>
    <mass value="1.0126620006859057"/>
    <inertia ixx="0.000815" iyy="0.001315" izz="0.001011" ixy="-0.000122" iyz="-8.2e-05" ixz="-0.000522"/>
  </inertial>
  <visual>
    <origin xyz="-0.00013 -0.229172 -0.040385" rpy="0 0 0"/>
    <geometry>
      <mesh filename="file://$(find hexapod_description)/meshes/leg_3_link_3_1.stl" scale="0.001 0.001 0.001"/>
    </geometry>
    <material name="silver"/>
  </visual>
  <collision>
    <origin xyz="-0.00013 -0.229172 -0.040385" rpy="0 0 0"/>
    <geometry>
      <mesh filename="file://$(find hexapod_description)/meshes/leg_3_link_3_1.stl" scale="0.001 0.001 0.001"/>
    </geometry>
  </collision>
</link>

<link name="leg_3_link_2_1">
  <inertial>
    <origin xyz="-0.038612908125580755 0.024931950622849613 0.03209860064693253" rpy="0 0 0"/>
    <mass value="0.2287158182027981"/>
    <inertia ixx="0.000293" iyy="0.000276" izz="0.000335" ixy="-2e-06" iyz="-3e-06" ixz="0.000126"/>
  </inertial>
  <visual>
    <origin xyz="0.067748 -0.197555 0.038827" rpy="0 0 0"/>
    <geometry>
      <mesh filename="file://$(find hexapod_description)/meshes/leg_3_link_2_1.stl" scale="0.001 0.001 0.001"/>
    </geometry>
    <material name="silver"/>
  </visual>
  <collision>
    <origin xyz="0.067748 -0.197555 0.038827" rpy="0 0 0"/>
    <geometry>
      <mesh filename="file://$(find hexapod_description)/meshes/leg_3_link_2_1.stl" scale="0.001 0.001 0.001"/>
    </geometry>
  </collision>
</link>

<link name="leg_3_link_1_1">
  <inertial>
    <origin xyz="-0.018585545303067386 0.028750059166235353 -0.023059753696741243" rpy="0 0 0"/>
    <mass value="0.9073986789846695"/>
    <inertia ixx="0.002786" iyy="0.003177" izz="0.00056" ixy="-2.4e-05" iyz="-1.5e-05" ixz="-0.000957"/>
  </inertial>
  <visual>
    <origin xyz="0.144246 -0.197611 -0.025579" rpy="0 0 0"/>
    <geometry>
      <mesh filename="file://$(find hexapod_description)/meshes/leg_3_link_1_1.stl" scale="0.001 0.001 0.001"/>
    </geometry>
    <material name="silver"/>
  </visual>
  <collision>
    <origin xyz="0.144246 -0.197611 -0.025579" rpy="0 0 0"/>
    <geometry>
      <mesh filename="file://$(find hexapod_description)/meshes/leg_3_link_1_1.stl" scale="0.001 0.001 0.001"/>
    </geometry>
  </collision>
</link>

<link name="leg_4_link_3_1">
  <inertial>
    <origin xyz="0.027827842510064177 0.004734636656079087 -0.05534052824142372" rpy="0 0 0"/>
    <mass value="1.0132520108724496"/>
    <inertia ixx="0.000814" iyy="0.001327" izz="0.001013" ixy="0.00011" iyz="-7e-05" ixz="0.000527"/>
  </inertial>
  <visual>
    <origin xyz="-0.212413 0.03383 -0.035672" rpy="0 0 0"/>
    <geometry>
      <mesh filename="file://$(find hexapod_description)/meshes/leg_4_link_3_1.stl" scale="0.001 0.001 0.001"/>
    </geometry>
    <material name="silver"/>
  </visual>
  <collision>
    <origin xyz="-0.212413 0.03383 -0.035672" rpy="0 0 0"/>
    <geometry>
      <mesh filename="file://$(find hexapod_description)/meshes/leg_4_link_3_1.stl" scale="0.001 0.001 0.001"/>
    </geometry>
  </collision>
</link>

<link name="leg_5_link_3_1">
  <inertial>
    <origin xyz="0.027727362528310262 0.005406300431649566 -0.05532850946625981" rpy="0 0 0"/>
    <mass value="1.0132520108724496"/>
    <inertia ixx="0.000808" iyy="0.001332" izz="0.001013" ixy="9.8e-05" iyz="-5.7e-05" ixz="0.000528"/>
  </inertial>
  <visual>
    <origin xyz="-0.22226 -0.096026 -0.037823" rpy="0 0 0"/>
    <geometry>
      <mesh filename="file://$(find hexapod_description)/meshes/leg_5_link_3_1.stl" scale="0.001 0.001 0.001"/>
    </geometry>
    <material name="silver"/>
  </visual>
  <collision>
    <origin xyz="-0.22226 -0.096026 -0.037823" rpy="0 0 0"/>
    <geometry>
      <mesh filename="file://$(find hexapod_description)/meshes/leg_5_link_3_1.stl" scale="0.001 0.001 0.001"/>
    </geometry>
  </collision>
</link>

<link name="leg_5_llink_2_1">
  <inertial>
    <origin xyz="0.03396675014480838 0.026560629165649705 0.0358235093671267" rpy="0 0 0"/>
    <mass value="0.22866968962750417"/>
    <inertia ixx="0.000318" iyy="0.000277" izz="0.00031" ixy="5e-06" iyz="-9e-06" ixz="-0.000127"/>
  </inertial>
  <visual>
    <origin xyz="-0.291986 -0.067645 0.041757" rpy="0 0 0"/>
    <geometry>
      <mesh filename="file://$(find hexapod_description)/meshes/leg_5_llink_2_1.stl" scale="0.001 0.001 0.001"/>
    </geometry>
    <material name="silver"/>
  </visual>
  <collision>
    <origin xyz="-0.291986 -0.067645 0.041757" rpy="0 0 0"/>
    <geometry>
      <mesh filename="file://$(find hexapod_description)/meshes/leg_5_llink_2_1.stl" scale="0.001 0.001 0.001"/>
    </geometry>
  </collision>
</link>

<link name="leg_5_link_1_1">
  <inertial>
    <origin xyz="0.015194262734185393 0.029558917275610747 -0.024828532452773375" rpy="0 0 0"/>
    <mass value="0.9074869947367368"/>
    <inertia ixx="0.002938" iyy="0.003182" izz="0.00041" ixy="1e-05" iyz="1.9e-05" ixz="0.000746"/>
  </inertial>
  <visual>
    <origin xyz="-0.361611 -0.070996 -0.029944" rpy="0 0 0"/>
    <geometry>
      <mesh filename="file://$(find hexapod_description)/meshes/leg_5_link_1_1.stl" scale="0.001 0.001 0.001"/>
    </geometry>
    <material name="silver"/>
  </visual>
  <collision>
    <origin xyz="-0.361611 -0.070996 -0.029944" rpy="0 0 0"/>
    <geometry>
      <mesh filename="file://$(find hexapod_description)/meshes/leg_5_link_1_1.stl" scale="0.001 0.001 0.001"/>
    </geometry>
  </collision>
</link>

<link name="leg_6_link_3_1">
  <inertial>
    <origin xyz="0.027727583128841132 0.005406596018310561 -0.055328604623189385" rpy="0 0 0"/>
    <mass value="1.0132520108724496"/>
    <inertia ixx="0.000808" iyy="0.001332" izz="0.001013" ixy="9.8e-05" iyz="-5.7e-05" ixz="0.000528"/>
  </inertial>
  <visual>
    <origin xyz="-0.216108 -0.226108 -0.040003" rpy="0 0 0"/>
    <geometry>
      <mesh filename="file://$(find hexapod_description)/meshes/leg_6_link_3_1.stl" scale="0.001 0.001 0.001"/>
    </geometry>
    <material name="silver"/>
  </visual>
  <collision>
    <origin xyz="-0.216108 -0.226108 -0.040003" rpy="0 0 0"/>
    <geometry>
      <mesh filename="file://$(find hexapod_description)/meshes/leg_6_link_3_1.stl" scale="0.001 0.001 0.001"/>
    </geometry>
  </collision>
</link>

<link name="leg_6_link_2_1">
  <inertial>
    <origin xyz="0.033966970745339664 0.02656092475231095 0.03582341421019737" rpy="0 0 0"/>
    <mass value="0.22866968962750417"/>
    <inertia ixx="0.000318" iyy="0.000277" izz="0.00031" ixy="5e-06" iyz="-9e-06" ixz="-0.000127"/>
  </inertial>
  <visual>
    <origin xyz="-0.285834 -0.197727 0.039577" rpy="0 0 0"/>
    <geometry>
      <mesh filename="file://$(find hexapod_description)/meshes/leg_6_link_2_1.stl" scale="0.001 0.001 0.001"/>
    </geometry>
    <material name="silver"/>
  </visual>
  <collision>
    <origin xyz="-0.285834 -0.197727 0.039577" rpy="0 0 0"/>
    <geometry>
      <mesh filename="file://$(find hexapod_description)/meshes/leg_6_link_2_1.stl" scale="0.001 0.001 0.001"/>
    </geometry>
  </collision>
</link>

<link name="leg_6_link_1_1">
  <inertial>
    <origin xyz="0.015193483334715818 0.029559212862271284 -0.024828627609704317" rpy="0 0 0"/>
    <mass value="0.9074869947367368"/>
    <inertia ixx="0.002938" iyy="0.003182" izz="0.00041" ixy="1e-05" iyz="1.9e-05" ixz="0.000746"/>
  </inertial>
  <visual>
    <origin xyz="-0.35546 -0.201078 -0.032124" rpy="0 0 0"/>
    <geometry>
      <mesh filename="file://$(find hexapod_description)/meshes/leg_6_link_1_1.stl" scale="0.001 0.001 0.001"/>
    </geometry>
    <material name="silver"/>
  </visual>
  <collision>
    <origin xyz="-0.35546 -0.201078 -0.032124" rpy="0 0 0"/>
    <geometry>
      <mesh filename="file://$(find hexapod_description)/meshes/leg_6_link_1_1.stl" scale="0.001 0.001 0.001"/>
    </geometry>
  </collision>
</link>

<link name="leg_2_link_3__1">
  <inertial>
    <origin xyz="-0.02799670252196973 0.004276094383967741 -0.055230856580649954" rpy="0 0 0"/>
    <mass value="1.0126607300527286"/>
    <inertia ixx="0.000815" iyy="0.001316" izz="0.001011" ixy="-0.000121" iyz="-8.1e-05" ixz="-0.000522"/>
  </inertial>
  <visual>
    <origin xyz="0.009716 -0.099316 -0.038233" rpy="0 0 0"/>
    <geometry>
      <mesh filename="file://$(find hexapod_description)/meshes/leg_2_link_3__1.stl" scale="0.001 0.001 0.001"/>
    </geometry>
    <material name="silver"/>
  </visual>
  <collision>
    <origin xyz="0.009716 -0.099316 -0.038233" rpy="0 0 0"/>
    <geometry>
      <mesh filename="file://$(find hexapod_description)/meshes/leg_2_link_3__1.stl" scale="0.001 0.001 0.001"/>
    </geometry>
  </collision>
</link>

<link name="leg_2_link_2_1">
  <inertial>
    <origin xyz="-0.03655269106835106 0.02492943001378764 0.034428145669553274" rpy="0 0 0"/>
    <mass value="0.22871574861196214"/>
    <inertia ixx="0.000308" iyy="0.000276" izz="0.00032" ixy="-2e-06" iyz="-3e-06" ixz="0.000128"/>
  </inertial>
  <visual>
    <origin xyz="0.077653 -0.06782 0.040976" rpy="0 0 0"/>
    <geometry>
      <mesh filename="file://$(find hexapod_description)/meshes/leg_2_link_2_1.stl" scale="0.001 0.001 0.001"/>
    </geometry>
    <material name="silver"/>
  </visual>
  <collision>
    <origin xyz="0.077653 -0.06782 0.040976" rpy="0 0 0"/>
    <geometry>
      <mesh filename="file://$(find hexapod_description)/meshes/leg_2_link_2_1.stl" scale="0.001 0.001 0.001"/>
    </geometry>
  </collision>
</link>

<link name="leg_2_link_1_1">
  <inertial>
    <origin xyz="-0.017401048235205913 0.028778315233383797 -0.023932405270489385" rpy="0 0 0"/>
    <mass value="0.9073984436402253"/>
    <inertia ixx="0.002871" iyy="0.003177" izz="0.000475" ixy="-2.3e-05" iyz="-1.6e-05" ixz="-0.000848"/>
  </inertial>
  <visual>
    <origin xyz="0.150058 -0.06787 -0.027999" rpy="0 0 0"/>
    <geometry>
      <mesh filename="file://$(find hexapod_description)/meshes/leg_2_link_1_1.stl" scale="0.001 0.001 0.001"/>
    </geometry>
    <material name="silver"/>
  </visual>
  <collision>
    <origin xyz="0.150058 -0.06787 -0.027999" rpy="0 0 0"/>
    <geometry>
      <mesh filename="file://$(find hexapod_description)/meshes/leg_2_link_1_1.stl" scale="0.001 0.001 0.001"/>
    </geometry>
  </collision>
</link>

<link name="leg_4_link_2_1">
  <inertial>
    <origin xyz="0.03461242398825387 0.025734686880203556 0.03580824475570928" rpy="0 0 0"/>
    <mass value="0.22866968962750417"/>
    <inertia ixx="0.000318" iyy="0.000276" izz="0.00031" ixy="4e-06" iyz="-6e-06" ixz="-0.000128"/>
  </inertial>
  <visual>
    <origin xyz="-0.281402 0.063887 0.043935" rpy="0 0 0"/>
    <geometry>
      <mesh filename="file://$(find hexapod_description)/meshes/leg_4_link_2_1.stl" scale="0.001 0.001 0.001"/>
    </geometry>
    <material name="silver"/>
  </visual>
  <collision>
    <origin xyz="-0.281402 0.063887 0.043935" rpy="0 0 0"/>
    <geometry>
      <mesh filename="file://$(find hexapod_description)/meshes/leg_4_link_2_1.stl" scale="0.001 0.001 0.001"/>
    </geometry>
  </collision>
</link>

<link name="leg_4_link_1_1">
  <inertial>
    <origin xyz="0.015892767008512 0.029183605213325997 -0.024836511563021524" rpy="0 0 0"/>
    <mass value="0.9074869947367368"/>
    <inertia ixx="0.002939" iyy="0.003181" izz="0.000409" ixy="1.6e-05" iyz="0.0" ixz="0.000745"/>
  </inertial>
  <visual>
    <origin xyz="-0.351117 0.062215 -0.027738" rpy="0 0 0"/>
    <geometry>
      <mesh filename="file://$(find hexapod_description)/meshes/leg_4_link_1_1.stl" scale="0.001 0.001 0.001"/>
    </geometry>
    <material name="silver"/>
  </visual>
  <collision>
    <origin xyz="-0.351117 0.062215 -0.027738" rpy="0 0 0"/>
    <geometry>
      <mesh filename="file://$(find hexapod_description)/meshes/leg_4_link_1_1.stl" scale="0.001 0.001 0.001"/>
    </geometry>
  </collision>
</link>

<joint name="Leg_1_coxa" type="revolute">
  <origin xyz="-0.003565 -0.030766 0.036053" rpy="0 0 0"/>
  <parent link="base_link"/>
  <child link="leg_1_link_2_1"/>
  <axis xyz="-0.001529 0.016683 -0.99986"/>
  <limit effort="100" lower="-1.57" upper="0.785" velocity="100"/>
  <dynamics damping="10" friction="0.1"/>
</joint>

<joint name="Leg_1_femur" type="revolute">
  <origin xyz="-0.067837 -0.031701 -0.079213" rpy="0 0 0"/>
  <parent link="leg_1_link_2_1"/>
  <child link="leg_1_link_3_1"/>
  <axis xyz="-0.013531 -0.99977 -0.016661"/>
  <limit effort="100" lower="-1.57" upper="1.57" velocity="100"/>
  <dynamics damping="10" friction="0.1"/>
</joint>

<joint name="Leg_1_tibia" type="revolute">
  <origin xyz="-0.072686 -0.00016 0.068679" rpy="0 0 0"/>
  <parent link="leg_1_link_3_1"/>
  <child link="leg_1_link_1_1"/>
  <axis xyz="-0.013531 -0.99977 -0.016661"/>
  <limit effort="100" lower="-1.57" upper="1.57" velocity="100"/>
  <dynamics damping="10" friction="0.1"/>
</joint>

<joint name="Leg_3_coxa" type="revolute">
  <origin xyz="0.00013 0.229172 0.040385" rpy="0 0 0"/>
  <parent link="base_link"/>
  <child link="leg_3_link_3_1"/>
  <axis xyz="-0.001529 0.016683 -0.99986"/>
  <limit effort="100" lower="-0.785" upper="1.57" velocity="100"/>
  <dynamics damping="10" friction="0.1"/>
</joint>

<joint name="Leg_3_femur" type="revolute">
  <origin xyz="-0.067878 -0.031617 -0.079212" rpy="0 0 0"/>
  <parent link="leg_3_link_3_1"/>
  <child link="leg_3_link_2_1"/>
  <axis xyz="-0.014767 -0.999752 -0.016659"/>
  <limit effort="100" lower="-1.57" upper="1.57" velocity="100"/>
  <dynamics damping="10" friction="0.1"/>
</joint>

<joint name="Leg_3_tibia" type="revolute">
  <origin xyz="-0.076498 5.6e-05 0.064406" rpy="0 0 0"/>
  <parent link="leg_3_link_2_1"/>
  <child link="leg_3_link_1_1"/>
  <axis xyz="-0.014767 -0.999752 -0.016659"/>
  <limit effort="100" lower="-1.57" upper="1.57" velocity="100"/>
  <dynamics damping="10" friction="0.1"/>
</joint>

<joint name="Leg_4_coxa" type="revolute">
  <origin xyz="0.212413 -0.03383 0.035672" rpy="0 0 0"/>
  <parent link="base_link"/>
  <child link="leg_4_link_3_1"/>
  <axis xyz="-0.001529 0.016683 -0.99986"/>
  <limit effort="100" lower="-0.785" upper="1.57" velocity="100"/>
  <dynamics damping="10" friction="0.1"/>
</joint>

<joint name="Leg_5_coxa" type="revolute">
  <origin xyz="0.22226 0.096026 0.037823" rpy="0 0 0"/>
  <parent link="base_link"/>
  <child link="leg_5_link_3_1"/>
  <axis xyz="-0.001529 0.016683 -0.99986"/>
  <limit effort="100" lower="-0.785" upper="0.785" velocity="100"/>
  <dynamics damping="10" friction="0.1"/>
</joint>

<joint name="Leg_5_femur" type="revolute">
  <origin xyz="0.069726 -0.028381 -0.07958" rpy="0 0 0"/>
  <parent link="leg_5_link_3_1"/>
  <child link="leg_5_llink_2_1"/>
  <axis xyz="0.065266 -0.997727 -0.016747"/>
  <limit effort="100" lower="-1.57" upper="1.57" velocity="100"/>
  <dynamics damping="10" friction="0.1"/>
</joint>

<joint name="Leg_5_tibia" type="revolute">
  <origin xyz="0.069625 0.003351 0.071701" rpy="0 0 0"/>
  <parent link="leg_5_llink_2_1"/>
  <child link="leg_5_link_1_1"/>
  <axis xyz="-0.065266 0.997727 0.016747"/>
  <limit effort="100" lower="-1.57" upper="1.57" velocity="100"/>
  <dynamics damping="10" friction="0.1"/>
</joint>

<joint name="Leg_6_coxa" type="revolute">
  <origin xyz="0.216108 0.226108 0.040003" rpy="0 0 0"/>
  <parent link="base_link"/>
  <child link="leg_6_link_3_1"/>
  <axis xyz="-0.001529 0.016683 -0.99986"/>
  <limit effort="100" lower="-1.57" upper="0.785" velocity="100"/>
  <dynamics damping="10" friction="0.1"/>
</joint>

<joint name="Leg_6_femur" type="revolute">
  <origin xyz="0.069726 -0.028381 -0.07958" rpy="0 0 0"/>
  <parent link="leg_6_link_3_1"/>
  <child link="leg_6_link_2_1"/>
  <axis xyz="0.065266 -0.997727 -0.016747"/>
  <limit effort="100" lower="-1.57" upper="1.57" velocity="100"/>
  <dynamics damping="10" friction="0.1"/>
</joint>

<joint name="Leg_6_tibia" type="revolute">
  <origin xyz="0.069626 0.003351 0.071701" rpy="0 0 0"/>
  <parent link="leg_6_link_2_1"/>
  <child link="leg_6_link_1_1"/>
  <axis xyz="-0.065266 0.997727 0.016747"/>
  <limit effort="100" lower="-1.57" upper="1.57" velocity="100"/>
  <dynamics damping="10" friction="0.1"/>
</joint>

<joint name="Leg_2_coxa" type="revolute">
  <origin xyz="-0.009716 0.099316 0.038233" rpy="0 0 0"/>
  <parent link="base_link"/>
  <child link="leg_2_link_3__1"/>
  <axis xyz="-0.001529 0.016683 -0.99986"/>
  <limit effort="100" lower="-0.785" upper="0.785" velocity="100"/>
  <dynamics damping="10" friction="0.1"/>
</joint>

<joint name="Leg_2_femur" type="revolute">
  <origin xyz="-0.067937 -0.031496 -0.079209" rpy="0 0 0"/>
  <parent link="leg_2_link_3__1"/>
  <child link="leg_2_link_2_1"/>
  <axis xyz="-0.016551 -0.999724 -0.016656"/>
  <limit effort="100" lower="-1.57" upper="1.57" velocity="100"/>
  <dynamics damping="10" friction="0.1"/>
</joint>

<joint name="Leg_2_tibia" type="revolute">
  <origin xyz="-0.072405 5e-05 0.068975" rpy="0 0 0"/>
  <parent link="leg_2_link_2_1"/>
  <child link="leg_2_link_1_1"/>
  <axis xyz="-0.016551 -0.999724 -0.016656"/>
  <limit effort="100" lower="-1.57" upper="1.57" velocity="100"/>
  <dynamics damping="10" friction="0.1"/>
</joint>

<joint name="Leg_4_femur" type="revolute">
  <origin xyz="0.068989 -0.030057 -0.079607" rpy="0 0 0"/>
  <parent link="leg_4_link_3_1"/>
  <child link="leg_4_link_2_1"/>
  <axis xyz="0.041169 -0.999012 -0.016732"/>
  <limit effort="100" lower="-1.57" upper="1.57" velocity="100"/>
  <dynamics damping="10" friction="0.1"/>
</joint>

<joint name="Leg_4_tibia" type="revolute">
  <origin xyz="0.069715 0.001672 0.071673" rpy="0 0 0"/>
  <parent link="leg_4_link_2_1"/>
  <child link="leg_4_link_1_1"/>
  <axis xyz="-0.041169 0.999012 0.016732"/>
  <limit effort="100" lower="-1.57" upper="1.57" velocity="100"/>
  <dynamics damping="10" friction="0.1"/>
</joint>

</robot>